<sdf version='1.7'>
  <world name='default'>
    <light name='sun' type='directional'>
      <cast_shadows>1</cast_shadows>
      <pose>0 0 10 0 -0 0</pose>
      <diffuse>0.8 0.8 0.8 1</diffuse>
      <specular>0.2 0.2 0.2 1</specular>
      <attenuation>
        <range>1000</range>
        <constant>0.9</constant>
        <linear>0.01</linear>
        <quadratic>0.001</quadratic>
      </attenuation>
      <direction>-0.5 0.1 -0.9</direction>
      <spot>
        <inner_angle>0</inner_angle>
        <outer_angle>0</outer_angle>
        <falloff>0</falloff>
      </spot>
    </light>
    <model name='ground_plane'>
      <static>1</static>
      <link name='link'>
        <collision name='collision'>
          <geometry>
            <plane>
              <normal>0 0 1</normal>
              <size>100 100</size>
            </plane>
          </geometry>
          <surface>
            <friction>
              <ode>
                <mu>100</mu>
                <mu2>50</mu2>
              </ode>
              <torsional>
                <ode/>
              </torsional>
            </friction>
            <contact>
              <ode/>
            </contact>
            <bounce/>
          </surface>
          <max_contacts>10</max_contacts>
        </collision>
        <visual name='visual'>
          <cast_shadows>0</cast_shadows>
          <geometry>
            <plane>
              <normal>0 0 1</normal>
              <size>100 100</size>
            </plane>
          </geometry>
          <material>
            <script>
              <uri>file://media/materials/scripts/gazebo.material</uri>
              <name>Gazebo/Grey</name>
            </script>
          </material>
        </visual>
        <self_collide>0</self_collide>
        <enable_wind>0</enable_wind>
        <kinematic>0</kinematic>
      </link>
    </model>
    <gravity>0 0 -9.8</gravity>
    <magnetic_field>6e-06 2.3e-05 -4.2e-05</magnetic_field>
    <atmosphere type='adiabatic'/>
    <physics type='ode'>
      <max_step_size>0.001</max_step_size>
      <real_time_factor>1</real_time_factor>
      <real_time_update_rate>1000</real_time_update_rate>
    </physics>
    <scene>
      <ambient>0.4 0.4 0.4 1</ambient>
      <background>0.7 0.7 0.7 1</background>
      <shadows>1</shadows>
    </scene>
    <audio>
      <device>default</device>
    </audio>
    <wind/>
    <spherical_coordinates>
      <surface_model>EARTH_WGS84</surface_model>
      <latitude_deg>0</latitude_deg>
      <longitude_deg>0</longitude_deg>
      <elevation>0</elevation>
      <heading_deg>0</heading_deg>
    </spherical_coordinates>
    <model name='turtlebot_nav_control'>
      <link name='base_footprint'>
        <inertial>
          <pose>-0.00429 0 0.030734 0 -0 0</pose>
          <mass>0.944735</mass>
          <inertia>
            <ixx>0.00717896</ixx>
            <ixy>-1.22941e-05</ixy>
            <ixz>0.00057674</ixz>
            <iyy>0.00721804</iyy>
            <iyz>-5.01209e-06</iyz>
            <izz>0.00413858</izz>
          </inertia>
        </inertial>
        <collision name='base_footprint_fixed_joint_lump__base_link_collision'>
          <pose>-0.032 0 0.08 0 -0 0</pose>
          <geometry>
            <box>
              <size>0.14 0.14 0.143</size>
            </box>
          </geometry>
          <max_contacts>10</max_contacts>
          <surface>
            <contact>
              <ode/>
            </contact>
            <bounce/>
            <friction>
              <torsional>
                <ode/>
              </torsional>
              <ode/>
            </friction>
          </surface>
        </collision>
        <collision name='base_footprint_fixed_joint_lump__caster_back_link_collision_1'>
          <pose>-0.081 1e-06 0.005 -1.57 0 0</pose>
          <geometry>
            <box>
              <size>0.03 0.009 0.02</size>
            </box>
          </geometry>
          <max_contacts>10</max_contacts>
          <surface>
            <contact>
              <ode/>
            </contact>
            <bounce/>
            <friction>
              <torsional>
                <ode/>
              </torsional>
              <ode/>
            </friction>
          </surface>
        </collision>
        <collision name='base_footprint_fixed_joint_lump__base_scan_collision_2'>
          <pose>-0.017 0 0.1755 0 -0 0</pose>
          <geometry>
            <cylinder>
              <length>0.0315</length>
              <radius>0.055</radius>
            </cylinder>
          </geometry>
          <surface>
            <contact>
              <ode/>
            </contact>
            <friction>
              <ode/>
              <torsional>
                <ode/>
              </torsional>
            </friction>
            <bounce/>
          </surface>
          <max_contacts>10</max_contacts>
        </collision>
        <visual name='base_footprint_fixed_joint_lump__base_link_visual'>
          <pose>-0.032 0 0.01 0 -0 0</pose>
          <geometry>
            <mesh>
              <scale>0.001 0.001 0.001</scale>
              <uri>model://turtlebot3_description/meshes/bases/burger_base.stl</uri>
            </mesh>
          </geometry>
        </visual>
        <visual name='base_footprint_fixed_joint_lump__base_scan_visual_1'>
          <pose>-0.032 0 0.182 0 -0 0</pose>
          <geometry>
            <mesh>
              <scale>0.001 0.001 0.001</scale>
              <uri>model://turtlebot3_description/meshes/sensors/lds.stl</uri>
            </mesh>
          </geometry>
        </visual>
        <sensor name='lds_hps' type='ray'>
          <always_on>1</always_on>
          <visualize>0</visualize>
          <update_rate>10</update_rate>
          <ray>
            <scan>
              <horizontal>
                <samples>360</samples>
                <resolution>1</resolution>
                <min_angle>0</min_angle>
                <max_angle>6.28319</max_angle>
              </horizontal>
              <vertical>
                <samples>1</samples>
                <min_angle>0</min_angle>
                <max_angle>0</max_angle>
              </vertical>
            </scan>
            <range>
              <min>0.12</min>
              <max>3.5</max>
              <resolution>0.01</resolution>
            </range>
          </ray>
          <plugin name='gazebo_ros_laser_controller' filename='libgazebo_ros_ray_sensor.so'>
            <ros>
              <argument>~/out:=scan</argument>
            </ros>
            <output_type>sensor_msgs/LaserScan</output_type>
            <frame_name>base_scan</frame_name>
          </plugin>
          <pose>-0.032 0 0.182 0 -0 0</pose>
        </sensor>
        <self_collide>0</self_collide>
        <enable_wind>0</enable_wind>
        <kinematic>0</kinematic>
      </link>
      <joint name='wheel_left_joint' type='revolute'>
        <pose relative_to='base_footprint'>0 0.08 0.033 -1.57 0 0</pose>
        <parent>base_footprint</parent>
        <child>wheel_left_link</child>
        <axis>
          <xyz>0 0 1</xyz>
          <limit>
            <lower>-1e+16</lower>
            <upper>1e+16</upper>
          </limit>
          <dynamics>
            <spring_reference>0</spring_reference>
            <spring_stiffness>0</spring_stiffness>
          </dynamics>
        </axis>
      </joint>
      <link name='wheel_left_link'>
        <pose relative_to='wheel_left_joint'>0 0 0 0 -0 0</pose>
        <inertial>
          <pose>0 0 0 0 -0 0</pose>
          <mass>0.0284989</mass>
          <inertia>
            <ixx>1.11756e-05</ixx>
            <ixy>-4.23698e-11</ixy>
            <ixz>-5.93817e-09</ixz>
            <iyy>1.11924e-05</iyy>
            <iyz>-1.44001e-11</iyz>
            <izz>2.07126e-05</izz>
          </inertia>
        </inertial>
        <collision name='wheel_left_link_collision'>
          <pose>0 0 0 0 -0 0</pose>
          <geometry>
            <cylinder>
              <length>0.018</length>
              <radius>0.033</radius>
            </cylinder>
          </geometry>
          <max_contacts>10</max_contacts>
          <surface>
            <contact>
              <ode/>
            </contact>
            <bounce/>
            <friction>
              <torsional>
                <ode/>
              </torsional>
              <ode/>
            </friction>
          </surface>
        </collision>
        <visual name='wheel_left_link_visual'>
          <pose>0 0 0 1.57 -0 0</pose>
          <geometry>
            <mesh>
              <scale>0.001 0.001 0.001</scale>
              <uri>model://turtlebot3_description/meshes/wheels/left_tire.stl</uri>
            </mesh>
          </geometry>
        </visual>
        <self_collide>0</self_collide>
        <enable_wind>0</enable_wind>
        <kinematic>0</kinematic>
      </link>
      <joint name='wheel_right_joint' type='revolute'>
        <pose relative_to='base_footprint'>0 -0.08 0.033 -1.57 0 0</pose>
        <parent>base_footprint</parent>
        <child>wheel_right_link</child>
        <axis>
          <xyz>0 0 1</xyz>
          <limit>
            <lower>-1e+16</lower>
            <upper>1e+16</upper>
          </limit>
          <dynamics>
            <spring_reference>0</spring_reference>
            <spring_stiffness>0</spring_stiffness>
          </dynamics>
        </axis>
      </joint>
      <link name='wheel_right_link'>
        <pose relative_to='wheel_right_joint'>0 0 0 0 -0 0</pose>
        <inertial>
          <pose>0 0 0 0 -0 0</pose>
          <mass>0.0284989</mass>
          <inertia>
            <ixx>1.11756e-05</ixx>
            <ixy>-4.23698e-11</ixy>
            <ixz>-5.93817e-09</ixz>
            <iyy>1.11924e-05</iyy>
            <iyz>-1.44001e-11</iyz>
            <izz>2.07126e-05</izz>
          </inertia>
        </inertial>
        <collision name='wheel_right_link_collision'>
          <pose>0 0 0 0 -0 0</pose>
          <geometry>
            <cylinder>
              <length>0.018</length>
              <radius>0.033</radius>
            </cylinder>
          </geometry>
          <max_contacts>10</max_contacts>
          <surface>
            <contact>
              <ode/>
            </contact>
            <bounce/>
            <friction>
              <torsional>
                <ode/>
              </torsional>
              <ode/>
            </friction>
          </surface>
        </collision>
        <visual name='wheel_right_link_visual'>
          <pose>0 0 0 1.57 -0 0</pose>
          <geometry>
            <mesh>
              <scale>0.001 0.001 0.001</scale>
              <uri>model://turtlebot3_description/meshes/wheels/right_tire.stl</uri>
            </mesh>
          </geometry>
        </visual>
        <self_collide>0</self_collide>
        <enable_wind>0</enable_wind>
        <kinematic>0</kinematic>
      </link>
      <static>0</static>
      <plugin name='gazebo_ros2_control' filename='libgazebo_ros2_control.so'>
        <parameters>/root/ros2_ws/install/turtlebot_nav_control/share/turtlebot_nav_control/config/controllers.yaml</parameters>
        <robot_param>robot_description</robot_param>
        <robot_param_node>robot_state_publisher</robot_param_node>
        <command_topic>cmd_vel</command_topic>
        <odometry_frame>odom</odometry_frame>
        <robot_base_frame>base_footprint</robot_base_frame>
      </plugin>
      <pose>0 0 0 0 -0 0</pose>
    </model>
    <model name='unit_cylinder'>
      <pose>1.14527 1.07696 0.5 0 -0 0</pose>
      <link name='link'>
        <inertial>
          <mass>1</mass>
          <inertia>
            <ixx>0.145833</ixx>
            <ixy>0</ixy>
            <ixz>0</ixz>
            <iyy>0.145833</iyy>
            <iyz>0</iyz>
            <izz>0.125</izz>
          </inertia>
          <pose>0 0 0 0 -0 0</pose>
        </inertial>
        <collision name='collision'>
          <geometry>
            <cylinder>
              <radius>0.5</radius>
              <length>1</length>
            </cylinder>
          </geometry>
          <max_contacts>10</max_contacts>
          <surface>
            <contact>
              <ode/>
            </contact>
            <bounce/>
            <friction>
              <torsional>
                <ode/>
              </torsional>
              <ode/>
            </friction>
          </surface>
        </collision>
        <visual name='visual'>
          <geometry>
            <cylinder>
              <radius>0.5</radius>
              <length>1</length>
            </cylinder>
          </geometry>
          <material>
            <script>
              <name>Gazebo/Grey</name>
              <uri>file://media/materials/scripts/gazebo.material</uri>
            </script>
          </material>
        </visual>
        <self_collide>0</self_collide>
        <enable_wind>0</enable_wind>
        <kinematic>0</kinematic>
      </link>
    </model>
    <state world_name='default'>
      <sim_time>153 352000000</sim_time>
      <real_time>170 712209147</real_time>
      <wall_time>1764047365 572124389</wall_time>
      <iterations>153352</iterations>
      <model name='ground_plane'>
        <pose>0 0 0 0 -0 0</pose>
        <scale>1 1 1</scale>
        <link name='link'>
          <pose>0 0 0 0 -0 0</pose>
          <velocity>0 0 0 0 -0 0</velocity>
          <acceleration>0 0 0 0 -0 0</acceleration>
          <wrench>0 0 0 0 -0 0</wrench>
        </link>
      </model>
      <model name='turtlebot_nav_control'>
        <pose>-0.000312 -0.017301 2e-06 -5.3e-05 -0.005158 -0.374708</pose>
        <scale>1 1 1</scale>
        <link name='base_footprint'>
          <pose>-0.000312 -0.017301 2e-06 -5.3e-05 -0.005158 -0.374708</pose>
          <velocity>-6e-05 0.000513 -0.000743 -0.046143 0.015559 0.044445</velocity>
          <acceleration>0.026781 0.243527 -1.50777 1.73755 0.313801 0.071508</acceleration>
          <wrench>0.025301 0.230068 -1.42444 0 -0 0</wrench>
        </link>
        <link name='wheel_left_link'>
          <pose>0.02881 0.057209 0.033 -1.57025 0.592657 -0.374394</pose>
          <velocity>-0.002668 0.003999 -0.005274 0.02333 -0.006601 0.043131</velocity>
          <acceleration>-0.555297 1.50924 -9.90826 -0.832337 0.462714 -2.96463</acceleration>
          <wrench>-0.015825 0.043012 -0.282374 0 -0 0</wrench>
        </link>
        <link name='wheel_right_link'>
          <pose>-0.02975 -0.091687 0.033006 1.56864 1.24443 2.76485</pose>
          <velocity>0.003708 0.000637 0.003254 -0.014634 0.12361 0.044568</velocity>
          <acceleration>0.926268 0.072166 6.40159 2.92662 -0.97251 2.75259</acceleration>
          <wrench>0.026398 0.002057 0.182438 0 -0 0</wrench>
        </link>
      </model>
      <model name='unit_cylinder'>
        <pose>1.5 1.5 0.499993 -4e-06 -4e-06 -0</pose>
        <scale>1 1 1</scale>
        <link name='link'>
          <pose>1.5 1.5 0.499993 -4e-06 -4e-06 -0</pose>
          <velocity>0 0 0 0 -0 0</velocity>
          <acceleration>0 0 -9.8 0 -0 0</acceleration>
          <wrench>0 0 -9.8 0 -0 0</wrench>
        </link>
      </model>
      <light name='sun'>
        <pose>0 0 10 0 -0 0</pose>
      </light>
    </state>
    <gui fullscreen='0'>
      <camera name='user_camera'>
        <pose>8.31241 -6.60765 2.94203 0 0.275643 2.35619</pose>
        <view_controller>orbit</view_controller>
        <projection_type>perspective</projection_type>
      </camera>
    </gui>
  </world>
</sdf>
